Workbook

Sheet F1
A1: FECHA 1 — 14-mar-2026 — CUBA Fátima
A2: Par 72 | Organizadores: Gatto + Zunino
A5: HCP | B5: cancha | C5: 5 | D5: 15 | E5: 1 | F5: 7 | G5: 11 | H5: 3 | I5: 17 | J5: 13 | K5: 9 | L5: 14 | M5: 10 | N5: 2 | O5: 6 | P5: 16 | Q5: 4 | R5: 12 | S5: 18 | T5: 8
A6: PAR | C6: 5 | D6: 3 | E6: 4 | F6: 5 | G6: 4 | H6: 4 | I6: 3 | J6: 4 | K6: 4 | L6: 4 | M6: 5 | N6: 4 | O6: 4 | P6: 3 | Q6: 4 | R6: 4 | S6: 3 | T6: 5
A7: Jugador | B7: Equipo | C7: H1 | D7: H2 | E7: H3 | F7: H4 | G7: H5 | H7: H6 | I7: H7 | J7: H8 | K7: H9 | L7: H10 | M7: H11 | N7: H12 | O7: H13 | P7: H14 | Q7: H15 | R7: H16 | S7: H17 | T7: H18 | U7: Gross | V7: Hdcp día | W7: Hdcp aplic | X7: Neto
A8: Gonzalez, Agus | B8: GRIS | C8: 5 | D8: 4 | E8: 5 | F8: 6 | G8: 5 | H8: 5 | I8: 3 | J8: 6 | K8: 6 | L8: 5 | M8: 7 | N8: 4 | O8: 6 | P8: 3 | Q8: 4 | R8: 4 | S8: 4 | T8: 4 | U8: =IF(COUNT(C8:T8)=18,SUM(C8:T8),"") | V8: 8 | W8: =IF(V8="","",MIN(V8,26)) | X8: =IF(OR(U8="",W8=""),"",U8-W8)
A9: Tarasido, Gonzalo | B9: GRIS | C9: 4 | D9: 4 | E9: 7 | F9: 5 | G9: 4 | H9: 5 | I9: 3 | J9: 3 | K9: 4 | L9: 5 | M9: 5 | N9: 5 | O9: 6 | P9: 5 | Q9: 6 | R9: 4 | S9: 4 | T9: 7 | U9: =IF(COUNT(C9:T9)=18,SUM(C9:T9),"") | V9: 11 | W9: =IF(V9="","",MIN(V9,26)) | X9: =IF(OR(U9="",W9=""),"",U9-W9)
A10: Zunino, Javi | B10: GRIS | C10: 7 | D10: 4 | E10: 4 | F10: 6 | G10: 7 | H10: 4 | I10: 4 | J10: 5 | K10: 4 | L10: 4 | M10: 5 | N10: 5 | O10: 4 | P10: 5 | Q10: 4 | R10: 4 | S10: 4 | T10: 7 | U10: =IF(COUNT(C10:T10)=18,SUM(C10:T10),"") | V10: 15 | W10: =IF(V10="","",MIN(V10,26)) | X10: =IF(OR(U10="",W10=""),"",U10-W10)
A11: Basaldua, Ignacio | B11: GRIS | C11: 7 | D11: 3 | E11: 6 | F11: 6 | G11: 7 | H11: 5 | I11: 3 | J11: 5 | K11: 6 | L11: 5 | M11: 8 | N11: 6 | O11: 6 | P11: 3 | Q11: 5 | R11: 6 | S11: 3 | T11: 6 | U11: =IF(COUNT(C11:T11)=18,SUM(C11:T11),"") | V11: 17 | W11: =IF(V11="","",MIN(V11,26)) | X11: =IF(OR(U11="",W11=""),"",U11-W11)
A12: Pannullo, Tincho | B12: GRIS | C12: 5 | D12: 4 | E12: 5 | F12: 8 | G12: 5 | H12: 6 | I12: 5 | J12: 7 | K12: 4 | L12: 6 | M12: 7 | N12: 5 | O12: 5 | P12: 3 | Q12: 7 | R12: 5 | S12: 5 | T12: 5 | U12: =IF(COUNT(C12:T12)=18,SUM(C12:T12),"") | V12: 15 | W12: =IF(V12="","",MIN(V12,26)) | X12: =IF(OR(U12="",W12=""),"",U12-W12)
A13: Benegas, Pancho | B13: GRIS | C13: 7 | D13: 4 | E13: 8 | F13: 8 | G13: 5 | H13: 7 | I13: 6 | J13: 7 | K13: 5 | L13: 6 | M13: 8 | N13: 5 | O13: 7 | P13: 4 | Q13: 5 | R13: 6 | S13: 6 | T13: 7 | U13: =IF(COUNT(C13:T13)=18,SUM(C13:T13),"") | V13: 19 | W13: =IF(V13="","",MIN(V13,26)) | X13: =IF(OR(U13="",W13=""),"",U13-W13)
A14: Guevara, Franki | B14: GRIS | C14: 5 | D14: 3 | E14: 6 | F14: 7 | G14: 5 | H14: 5 | I14: 4 | J14: 5 | K14: 4 | L14: 4 | M14: 7 | N14: 4 | O14: 5 | P14: 4 | Q14: 7 | R14: 6 | S14: 2 | T14: 4 | U14: =IF(COUNT(C14:T14)=18,SUM(C14:T14),"") | V14: 20 | W14: =IF(V14="","",MIN(V14,26)) | X14: =IF(OR(U14="",W14=""),"",U14-W14)
A15: Dipaola, Martin | B15: GRIS | C15: 5 | D15: 4 | E15: 4 | F15: 7 | G15: 6 | H15: 5 | I15: 4 | J15: 6 | K15: 4 | L15: 6 | M15: 6 | N15: 6 | O15: 6 | P15: 3 | Q15: 6 | R15: 4 | S15: 3 | T15: 8 | U15: =IF(COUNT(C15:T15)=18,SUM(C15:T15),"") | V15: 22 | W15: =IF(V15="","",MIN(V15,26)) | X15: =IF(OR(U15="",W15=""),"",U15-W15)
A16: Gatto, Mariano | B16: ROJO | C16: 5 | D16: 4 | E16: 5 | F16: 6 | G16: 4 | H16: 6 | I16: 3 | J16: 5 | K16: 5 | L16: 6 | M16: 6 | N16: 6 | O16: 4 | P16: 3 | Q16: 3 | R16: 3 | S16: 3 | T16: 5 | U16: =IF(COUNT(C16:T16)=18,SUM(C16:T16),"") | V16: 10 | W16: =IF(V16="","",MIN(V16,26)) | X16: =IF(OR(U16="",W16=""),"",U16-W16)
A17: Elizalde, Juancho | B17: ROJO | C17: 6 | D17: 5 | E17: 5 | F17: 7 | G17: 4 | H17: 6 | I17: 3 | J17: 3 | K17: 5 | L17: 5 | M17: 6 | N17: 5 | O17: 4 | P17: 2 | Q17: 6 | R17: 4 | S17: 5 | T17: 5 | U17: =IF(COUNT(C17:T17)=18,SUM(C17:T17),"") | V17: 13 | W17: =IF(V17="","",MIN(V17,26)) | X17: =IF(OR(U17="",W17=""),"",U17-W17)
A18: Canónico, Agus | B18: ROJO | C18: 5 | D18: 4 | E18: 7 | F18: 7 | G18: 5 | H18: 5 | I18: 4 | J18: 5 | K18: 5 | L18: 7 | M18: 6 | N18: 5 | O18: 6 | P18: 3 | Q18: 5 | R18: 5 | S18: 5 | T18: 7 | U18: =IF(COUNT(C18:T18)=18,SUM(C18:T18),"") | V18: 18 | W18: =IF(V18="","",MIN(V18,26)) | X18: =IF(OR(U18="",W18=""),"",U18-W18)
A19: Vogelius, Nico | B19: ROJO | C19: 7 | D19: 3 | E19: 4 | F19: 5 | G19: 4 | H19: 6 | I19: 3 | J19: 5 | K19: 6 | L19: 5 | M19: 6 | N19: 4 | O19: 4 | P19: 3 | Q19: 6 | R19: 5 | S19: 3 | T19: 5 | U19: =IF(COUNT(C19:T19)=18,SUM(C19:T19),"") | V19: 17 | W19: =IF(V19="","",MIN(V19,26)) | X19: =IF(OR(U19="",W19=""),"",U19-W19)
... A22: Scapparone, Nico | B22: ROJO | C22: 4 | D22: 4 | E22: 7 | F22: 5 | G22: 6 | H22: 7 | I22: 5 | J22: 3 | K22: 4 | L22: 4 | M22: 8 | N22: 6 | O22: 7 | P22: 5 | Q22: 6 | R22: 5 | S22: 4 | T22: 5 | U22: =IF(COUNT(C22:T22)=18,SUM(C22:T22),"") | V22: 20 | W22: =IF(V22="","",MIN(V22,26)) | X22: =IF(OR(U22="",W22=""),"",U22-W22)
A23: Gatto, Alejandro | B23: ROJO | U23: 117 | V23: 20 | W23: =IF(V23="","",MIN(V23,26)) | X23: =IF(OR(U23="",W23=""),"",U23-W23)

Sheet F2
A1: FECHA 2 — 11 Abr 2026 — CUBA Fátima
A2: Par 72 | Organizadores: —
A5: HCP | B5: cancha | C5: 5 | D5: 15 | E5: 1 | F5: 7 | G5: 11 | H5: 3 | I5: 17 | J5: 13 | K5: 9 | L5: 14 | M5: 10 | N5: 2 | O5: 6 | P5: 16 | Q5: 4 | R5: 12 | S5: 18 | T5: 8
A6: PAR | C6: 5 | D6: 3 | E6: 4 | F6: 5 | G6: 4 | H6: 4 | I6: 3 | J6: 4 | K6: 4 | L6: 4 | M6: 5 | N6: 4 | O6: 4 | P6: 3 | Q6: 4 | R6: 4 | S6: 3 | T6: 5
A7: Jugador | B7: Equipo | C7: H1 | D7: H2 | E7: H3 | F7: H4 | G7: H5 | H7: H6 | I7: H7 | J7: H8 | K7: H9 | L7: H10 | M7: H11 | N7: H12 | O7: H13 | P7: H14 | Q7: H15 | R7: H16 | S7: H17 | T7: H18 | U7: Gross | V7: Hdcp día | W7: Hdcp aplic | X7: Neto
A8: Tarasido, Gonzalo | B8: GRIS | C8: 5 | D8: 4 | E8: 8 | F8: 6 | G8: 7 | H8: 7 | I8: 6 | J8: 4 | K8: 6 | L8: 4 | M8: 5 | N8: 4 | O8: 6 | P8: 4 | Q8: 4 | R8: 5 | S8: 5 | T8: 7 | U8: =IF(COUNT(C8:T8)=18,SUM(C8:T8),"") | V8: 12 | W8: =IF(V8="","",MIN(V8,26)) | X8: =IF(OR(U8="",W8=""),"",U8-W8)
A9: Pannullo, Tincho | B9: GRIS | C9: 5 | D9: 5 | E9: 5 | F9: 9 | G9: 6 | H9: 5 | I9: 5 | J9: 4 | K9: 6 | L9: 5 | M9: 5 | N9: 6 | O9: 3 | P9: 4 | Q9: 6 | R9: 6 | S9: 2 | T9: 5 | U9: =IF(COUNT(C9:T9)=18,SUM(C9:T9),"") | V9: 15 | W9: =IF(V9="","",MIN(V9,26)) | X9: =IF(OR(U9="",W9=""),"",U9-W9)
A10: Benegas, Pancho | B10: GRIS | C10: 8 | D10: 3 | E10: 4 | F10: 6 | G10: 5 | H10: 5 | I10: 4 | J10: 6 | K10: 6 | L10: 6 | M10: 5 | N10: 5 | O10: 5 | P10: 4 | Q10: 6 | R10: 6 | S10: 3 | T10: 6 | U10: =IF(COUNT(C10:T10)=18,SUM(C10:T10),"") | V10: 20 | W10: =IF(V10="","",MIN(V10,26)) | X10: =IF(OR(U10="",W10=""),"",U10-W10)
A11: Guevara, Franki | B11: GRIS | C11: 5 | D11: 5 | E11: 5 | F11: 7 | G11: 6 | H11: 6 | I11: 3 | J11: 6 | K11: 6 | L11: 4 | M11: 6 | N11: 5 | O11: 7 | P11: 4 | Q11: 5 | R11: 7 | S11: 3 | T11: 5 | U11: =IF(COUNT(C11:T11)=18,SUM(C11:T11),"") | V11: 20 | W11: =IF(V11="","",MIN(V11,26)) | X11: =IF(OR(U11="",W11=""),"",U11-W11)
A12: Dipaola, Martin | B12: GRIS | C12: 6 | D12: 4 | E12: 6 | F12: 8 | G12: 5 | H12: 6 | I12: 4 | J12: 4 | K12: 5 | L12: 5 | M12: 4 | N12: 5 | O12: 7 | P12: 7 | Q12: 6 | R12: 5 | S12: 4 | T12: 4 | U12: =IF(COUNT(C12:T12)=18,SUM(C12:T12),"") | V12: 22 | W12: =IF(V12="","",MIN(V12,26)) | X12: =IF(OR(U12="",W12=""),"",U12-W12)
A13: Gatto, Mariano | B13: ROJO | C13: 4 | D13: 3 | E13: 4 | F13: 6 | G13: 4 | H13: 4 | I13: 3 | J13: 3 | K13: 4 | L13: 6 | M13: 5 | N13: 4 | O13: 4 | P13: 2 | Q13: 5 | R13: 4 | S13: 3 | T13: 7 | U13: =IF(COUNT(C13:T13)=18,SUM(C13:T13),"") | V13: 9 | W13: =IF(V13="","",MIN(V13,26)) | X13: =IF(OR(U13="",W13=""),"",U13-W13)
A14: Elizalde, Juancho | B14: ROJO | C14: 6 | D14: 4 | E14: 4 | F14: 6 | G14: 5 | H14: 5 | I14: 4 | J14: 7 | K14: 3 | L14: 4 | M14: 5 | N14: 5 | O14: 6 | P14: 3 | Q14: 4 | R14: 4 | S14: 3 | T14: 5 | U14: =IF(COUNT(C14:T14)=18,SUM(C14:T14),"") | V14: 13 | W14: =IF(V14="","",MIN(V14,26)) | X14: =IF(OR(U14="",W14=""),"",U14-W14)
A15: Canónico, Agus | B15: ROJO | C15: 8 | D15: 5 | E15: 4 | F15: 6 | G15: 4 | H15: 5 | I15: 2 | J15: 5 | K15: 6 | L15: 4 | M15: 7 | N15: 5 | O15: 4 | P15: 4 | Q15: 5 | R15: 5 | S15: 5 | T15: 7 | U15: =IF(COUNT(C15:T15)=18,SUM(C15:T15),"") | V15: 18 | W15: =IF(V15="","",MIN(V15,26)) | X15: =IF(OR(U15="",W15=""),"",U15-W15)
A16: Vogelius, Nico | B16: ROJO | C16: 8 | D16: 3 | E16: 7 | F16: 7 | G16: 5 | H16: 5 | I16: 3 | J16: 5 | K16: 5 | L16: 7 | M16: 6 | N16: 5 | O16: 5 | P16: 5 | Q16: 8 | R16: 6 | S16: 4 | T16: 6 | U16: =IF(COUNT(C16:T16)=18,SUM(C16:T16),"") | V16: 15 | W16: =IF(V16="","",MIN(V16,26)) | X16: =IF(OR(U16="",W16=""),"",U16-W16)
A17: Mendez, Pato | B17: ROJO | C17: 5 | D17: 3 | E17: 5 | F17: 7 | G17: 5 | H17: 6 | I17: 4 | J17: 5 | K17: 4 | L17: 6 | M17: 6 | N17: 4 | O17: 4 | P17: 4 | Q17: 6 | R17: 5 | S17: 4 | T17: 7 | U17: =IF(COUNT(C17:T17)=18,SUM(C17:T17),"") | V17: 16 | W17: =IF(V17="","",MIN(V17,26)) | X17: =IF(OR(U17="",W17=""),"",U17-W17)
A18: Molinario, Andy | B18: ROJO | C18: 6 | D18: 5 | E18: 6 | F18: 6 | G18: 7 | H18: 4 | I18: 4 | J18: 4 | K18: 7 | L18: 6 | M18: 5 | N18: 5 | O18: 5 | P18: 3 | Q18: 4 | R18: 4 | S18: 6 | T18: 6 | U18: =IF(COUNT(C18:T18)=18,SUM(C18:T18),"") | V18: 17 | W18: =IF(V18="","",MIN(V18,26)) | X18: =IF(OR(U18="",W18=""),"",U18-W18)
A19: Fernandez, Lucas | B19: ROJO | C19: 6 | D19: 4 | E19: 5 | F19: 6 | G19: 4 | H19: 5 | I19: 4 | J19: 5 | K19: 5 | L19: 4 | M19: 4 | N19: 5 | O19: 5 | P19: 6 | Q19: 6 | R19: 6 | S19: 4 | T19: 7 | U19: =IF(COUNT(C19:T19)=18,SUM(C19:T19),"") | V19: 21 | W19: =IF(V19="","",MIN(V19,26)) | X19: =IF(OR(U19="",W19=""),"",U19-W19)
A20: Gatto, Alejandro | B20: ROJO | C20: 9 | D20: 4 | E20: 7 | F20: 9 | G20: 6 | H20: 6 | I20: 4 | J20: 4 | K20: 4 | L20: 7 | M20: 6 | N20: 7 | O20: 4 | P20: 3 | Q20: 9 | R20: 7 | S20: 3 | T20: 8 | U20: =IF(COUNT(C20:T20)=18,SUM(C20:T20),"") | V20: 18 | W20: =IF(V20="","",MIN(V20,26)) | X20: =IF(OR(U20="",W20=""),"",U20-W20)
A21: sup_shaw | B21: — | C21: 5 | D21: 4 | E21: 5 | F21: 8 | G21: 6 | H21: 5 | I21: 3 | J21: 4 | K21: 4 | L21: 5 | M21: 5 | N21: 5 | O21: 5 | P21: 3 | Q21: 4 | R21: 4 | S21: 4 | T21: 4 | U21: =IF(COUNT(C21:T21)=18,SUM(C21:T21),"") | W21: =IF(V21="","",MIN(V21,26)) | X21: =IF(OR(U21="",W21=""),"",U21-W21)

Sheet F3
A1: FECHA 3 — 09 May 2026 — SHA Hebraica
A2: Par 72 | Organizadores: Gonzalez + Tarasido
A5: HCP | B5: cancha | C5: 15 | D5: 5 | E5: 9 | F5: 7 | G5: 11 | H5: 3 | I5: 1 | J5: 17 | K5: 13 | L5: 10 | M5: 14 | N5: 2 | O5: 12 | P5: 8 | Q5: 18 | R5: 16 | S5: 4 | T5: 6
A6: PAR | C6: 5 | D6: 5 | E6: 4 | F6: 4 | G6: 3 | H6: 4 | I6: 5 | J6: 3 | K6: 4 | L6: 4 | M6: 3 | N6: 5 | O6: 3 | P6: 5 | Q6: 3 | R6: 4 | S6: 4 | T6: 4
A7: Jugador | B7: Equipo | C7: H1 | D7: H2 | E7: H3 | F7: H4 | G7: H5 | H7: H6 | I7: H7 | J7: H8 | K7: H9 | L7: H10 | M7: H11 | N7: H12 | O7: H13 | P7: H14 | Q7: H15 | R7: H16 | S7: H17 | T7: H18 | U7: Gross | V7: Hdcp día | W7: Hdcp aplic | X7: Neto
A8: Tarasido, Gonzalo | B8: GRIS | C8: 5 | D8: 7 | E8: 5 | F8: 4 | G8: 4 | H8: 6 | I8: 7 | J8: 3 | K8: 5 | L8: 4 | M8: 3 | N8: 6 | O8: 4 | P8: 5 | Q8: 2 | R8: 6 | S8: 5 | T8: 5 | U8: =IF(COUNT(C8:T8)=18,SUM(C8:T8),"") | V8: 10 | W8: =IF(V8="","",MIN(V8,26)) | X8: =IF(OR(U8="",W8=""),"",U8-W8)
A9: Basaldua, Ignacio | B9: GRIS | C9: 5 | D9: 6 | E9: 5 | F9: 4 | G9: 4 | H9: 5 | I9: 6 | J9: 4 | K9: 5 | L9: 5 | M9: 3 | N9: 6 | O9: 6 | P9: 5 | Q9: 4 | R9: 6 | S9: 6 | T9: 6 | U9: =IF(COUNT(C9:T9)=18,SUM(C9:T9),"") | V9: 13 | W9: =IF(V9="","",MIN(V9,26)) | X9: =IF(OR(U9="",W9=""),"",U9-W9)
A10: Pannullo, Tincho | B10: GRIS | C10: 5 | D10: 8 | E10: 6 | F10: 5 | G10: 3 | H10: 5 | I10: 6 | J10: 3 | K10: 5 | L10: 4 | M10: 4 | N10: 6 | O10: 7 | P10: 6 | Q10: 4 | R10: 6 | S10: 6 | T10: 5 | U10: =IF(COUNT(C10:T10)=18,SUM(C10:T10),"") | V10: 17 | W10: =IF(V10="","",MIN(V10,26)) | X10: =IF(OR(U10="",W10=""),"",U10-W10)
A11: Benegas, Pancho | B11: GRIS | C11: 5 | D11: 6 | E11: 7 | F11: 5 | G11: 3 | H11: 5 | I11: 8 | J11: 4 | K11: 6 | L11: 5 | M11: 2 | N11: 6 | O11: 5 | P11: 7 | Q11: 5 | R11: 6 | S11: 8 | T11: 6 | U11: =IF(COUNT(C11:T11)=18,SUM(C11:T11),"") | V11: 21 | W11: =IF(V11="","",MIN(V11,26)) | X11: =IF(OR(U11="",W11=""),"",U11-W11)
A12: Guevara, Franki | B12: GRIS | C12: 7 | D12: 6 | E12: 6 | F12: 5 | G12: 7 | H12: 6 | I12: 8 | J12: 4 | K12: 5 | L12: 5 | M12: 4 | N12: 7 | O12: 4 | P12: 6 | Q12: 4 | R12: 5 | S12: 6 | T12: 6 | U12: =IF(COUNT(C12:T12)=18,SUM(C12:T12),"") | V12: 21 | W12: =IF(V12="","",MIN(V12,26)) | X12: =IF(OR(U12="",W12=""),"",U12-W12)
A13: Dipaola, Martin | B13: GRIS | C13: 6 | D13: 7 | E13: 6 | F13: 5 | G13: 4 | H13: 8 | I13: 8 | J13: 4 | K13: 6 | L13: 6 | M13: 3 | N13: 6 | O13: 10 | P13: 9 | Q13: 3 | R13: 6 | S13: 5 | T13: 8 | U13: =IF(COUNT(C13:T13)=18,SUM(C13:T13),"") | V13: 27 | W13: =IF(V13="","",MIN(V13,26)) | X13: =IF(OR(U13="",W13=""),"",U13-W13)
A14: Gatto, Mariano | B14: ROJO | C14: 5 | D14: 7 | E14: 5 | F14: 5 | G14: 4 | H14: 6 | I14: 5 | J14: 3 | K14: 5 | L14: 4 | M14: 6 | N14: 4 | O14: 4 | P14: 6 | Q14: 6 | R14: 7 | S14: 4 | T14: 5 | U14: =IF(COUNT(C14:T14)=18,SUM(C14:T14),"") | V14: 6 | W14: =IF(V14="","",MIN(V14,26)) | X14: =IF(OR(U14="",W14=""),"",U14-W14)
A15: Elizalde, Juancho | B15: ROJO | C15: 7 | D15: 5 | E15: 6 | F15: 4 | G15: 3 | H15: 4 | I15: 6 | J15: 3 | K15: 7 | L15: 6 | M15: 3 | N15: 8 | O15: 4 | P15: 5 | Q15: 3 | R15: 4 | S15: 6 | T15: 6 | U15: =IF(COUNT(C15:T15)=18,SUM(C15:T15),"") | V15: 11 | W15: =IF(V15="","",MIN(V15,26)) | X15: =IF(OR(U15="",W15=""),"",U15-W15)
A16: Canónico, Agus | B16: ROJO | C16: 6 | D16: 5 | E16: 6 | F16: 8 | G16: 5 | H16: 7 | I16: 9 | J16: 3 | K16: 5 | L16: 5 | M16: 3 | N16: 7 | O16: 4 | P16: 6 | Q16: 3 | R16: 5 | S16: 5 | T16: 6 | U16: =IF(COUNT(C16:T16)=18,SUM(C16:T16),"") | V16: 16 | W16: =IF(V16="","",MIN(V16,26)) | X16: =IF(OR(U16="",W16=""),"",U16-W16)
A17: Vogelius, Nico | B17: ROJO | C17: 6 | D17: 5 | E17: 5 | F17: 5 | G17: 4 | H17: 4 | I17: 9 | J17: 4 | K17: 5 | L17: 4 | M17: 4 | N17: 6 | O17: 5 | P17: 7 | Q17: 4 | R17: 4 | S17: 4 | T17: 5 | U17: =IF(COUNT(C17:T17)=18,SUM(C17:T17),"") | V17: 12 | W17: =IF(V17="","",MIN(V17,26)) | X17: =IF(OR(U17="",W17=""),"",U17-W17)
A18: Mendez, Pato | B18: ROJO | C18: 6 | D18: 6 | E18: 6 | F18: 6 | G18: 5 | H18: 5 | I18: 7 | J18: 4 | K18: 8 | L18: 5 | M18: 6 | N18: 5 | O18: 4 | P18: 8 | Q18: 5 | R18: 5 | S18: 6 | T18: 5 | U18: =IF(COUNT(C18:T18)=18,SUM(C18:T18),"") | V18: 17 | W18: =IF(V18="","",MIN(V18,26)) | X18: =IF(OR(U18="",W18=""),"",U18-W18)
A19: Molinario, Andy | B19: ROJO | C19: 6 | D19: 6 | E19: 5 | F19: 7 | G19: 4 | H19: 6 | I19: 6 | J19: 4 | K19: 6 | L19: 7 | M19: 4 | N19: 7 | O19: 7 | P19: 7 | Q19: 2 | R19: 6 | S19: 6 | T19: 6 | U19: =IF(COUNT(C19:T19)=18,SUM(C19:T19),"") | V19: 18 | W19: =IF(V19="","",MIN(V19,26)) | X19: =IF(OR(U19="",W19=""),"",U19-W19)
... A22: Alfonso, Juan Ignacio | B22: ROJO | C22: 5 | D22: 7 | E22: 5 | F22: 4 | G22: 4 | H22: 10 | I22: 7 | J22: 5 | K22: 6 | L22: 4 | M22: 5 | N22: 10 | O22: 5 | P22: 8 | Q22: 2 | R22: 5 | S22: 5 | T22: 7 | U22: =IF(COUNT(C22:T22)=18,SUM(C22:T22),"") | V22: 20 | W22: =IF(V22="","",MIN(V22,26)) | X22: =IF(OR(U22="",W22=""),"",U22-W22)

Sheet F5
A1: FECHA 5 — 04 Jul 2026 — La Orquídea Golf
A2: Par 72 | Organizadores: Basaldua + Canónico
A5: HCP | B5: cancha | C5: 9 | D5: 1 | E5: 17 | F5: 7 | G5: 11 | H5: 15 | I5: 3 | J5: 5 | K5: 13 | L5: 8 | M5: 10 | N5: 4 | O5: 6 | P5: 2 | Q5: 18 | R5: 12 | S5: 14 | T5: 16
A6: PAR | C6: 4 | D6: 5 | E6: 4 | F6: 3 | G6: 4 | H6: 5 | I6: 4 | J6: 4 | K6: 3 | L6: 5 | M6: 4 | N6: 4 | O6: 4 | P6: 4 | Q6: 3 | R6: 4 | S6: 3 | T6: 5
A7: Jugador | B7: Equipo | C7: H1 | D7: H2 | E7: H3 | F7: H4 | G7: H5 | H7: H6 | I7: H7 | J7: H8 | K7: H9 | L7: H10 | M7: H11 | N7: H12 | O7: H13 | P7: H14 | Q7: H15 | R7: H16 | S7: H17 | T7: H18 | U7: Gross | V7: Hdcp día | W7: Hdcp aplic | X7: Neto
A8: Gonzalez, Agus | B8: GRIS | C8: 5 | D8: 9 | E8: 5 | F8: 2 | G8: 7 | H8: 7 | I8: 5 | J8: 5 | K8: 3 | L8: 6 | M8: 4 | N8: 5 | O8: 5 | P8: 5 | Q8: 3 | R8: 4 | S8: 3 | T8: 5 | U8: =IF(COUNT(C8:T8)=18,SUM(C8:T8),"") | V8: 5 | W8: =IF(V8="","",MIN(V8,26)) | X8: =IF(OR(U8="",W8=""),"",U8-W8)
A9: Tarasido, Gonzalo | B9: GRIS | C9: 4 | D9: 7 | E9: 5 | F9: 3 | G9: 4 | H9: 6 | I9: 7 | J9: 5 | K9: 3 | L9: 9 | M9: 5 | N9: 5 | O9: 5 | P9: 7 | Q9: 4 | R9: 4 | S9: 3 | T9: 6 | U9: =IF(COUNT(C9:T9)=18,SUM(C9:T9),"") | V9: 11 | W9: =IF(V9="","",MIN(V9,26)) | X9: =IF(OR(U9="",W9=""),"",U9-W9)
A10: Zunino, Javi | B10: GRIS | U10: =IF(COUNT(C10:T10)=18,SUM(C10:T10),"") | W10: =IF(V10="","",MIN(V10,26)) | X10: =IF(OR(U10="",W10=""),"",U10-W10)
A11: Basaldua, Ignacio | B11: GRIS | C11: 4 | D11: 7 | E11: 4 | F11: 3 | G11: 8 | H11: 6 | I11: 5 | J11: 5 | K11: 3 | L11: 5 | M11: 5 | N11: 4 | O11: 4 | P11: 5 | Q11: 8 | R11: 4 | S11: 6 | T11: 7 | U11: =IF(COUNT(C11:T11)=18,SUM(C11:T11),"") | V11: 15 | W11: =IF(V11="","",MIN(V11,26)) | X11: =IF(OR(U11="",W11=""),"",U11-W11)
A12: Benegas, Pancho | B12: GRIS | C12: 4 | D12: 9 | E12: 4 | F12: 5 | G12: 4 | H12: 9 | I12: 7 | J12: 8 | K12: 6 | L12: 8 | M12: 5 | N12: 5 | O12: 4 | P12: 5 | Q12: 6 | R12: 6 | S12: 3 | T12: 5 | U12: =IF(COUNT(C12:T12)=18,SUM(C12:T12),"") | V12: 23 | W12: =IF(V12="","",MIN(V12,26)) | X12: =IF(OR(U12="",W12=""),"",U12-W12)
A13: Guevara, Franki | B13: GRIS | C13: 6 | D13: 7 | E13: 5 | F13: 4 | G13: 5 | H13: 5 | I13: 7 | J13: 6 | K13: 6 | L13: 7 | M13: 6 | N13: 5 | O13: 5 | P13: 5 | Q13: 6 | R13: 5 | S13: 4 | T13: 7 | U13: =IF(COUNT(C13:T13)=18,SUM(C13:T13),"") | V13: 23 | W13: =IF(V13="","",MIN(V13,26)) | X13: =IF(OR(U13="",W13=""),"",U13-W13)
A14: Dipaola, Martin | B14: GRIS | C14: 11 | D14: 7 | E14: 5 | F14: 7 | G14: 5 | H14: 8 | I14: 4 | J14: 7 | K14: 5 | L14: 8 | M14: 5 | N14: 6 | O14: 7 | P14: 6 | Q14: 6 | R14: 6 | S14: 4 | T14: 7 | U14: =IF(COUNT(C14:T14)=18,SUM(C14:T14),"") | V14: 30 | W14: =IF(V14="","",MIN(V14,26)) | X14: =IF(OR(U14="",W14=""),"",U14-W14)
A15: Gatto, Mariano | B15: ROJO | C15: 6 | D15: 7 | E15: 4 | F15: 4 | G15: 6 | H15: 4 | I15: 4 | J15: 4 | K15: 4 | L15: 6 | M15: 6 | N15: 3 | O15: 6 | P15: 5 | Q15: 3 | R15: 4 | S15: 3 | T15: 6 | U15: =IF(COUNT(C15:T15)=18,SUM(C15:T15),"") | V15: 7 | W15: =IF(V15="","",MIN(V15,26)) | X15: =IF(OR(U15="",W15=""),"",U15-W15)
A16: Elizalde, Juancho | B16: ROJO | C16: 5 | D16: 5 | E16: 4 | F16: 4 | G16: 5 | H16: 5 | I16: 5 | J16: 6 | K16: 3 | L16: 6 | M16: 5 | N16: 4 | O16: 5 | P16: 4 | Q16: 3 | R16: 4 | S16: 3 | T16: 10 | U16: =IF(COUNT(C16:T16)=18,SUM(C16:T16),"") | V16: 12 | W16: =IF(V16="","",MIN(V16,26)) | X16: =IF(OR(U16="",W16=""),"",U16-W16)
A17: Canónico, Agus | B17: ROJO | C17: 5 | D17: 7 | E17: 4 | F17: 4 | G17: 4 | H17: 5 | I17: 9 | J17: 6 | K17: 7 | L17: 6 | M17: 5 | N17: 5 | O17: 5 | P17: 8 | Q17: 7 | R17: 5 | S17: 4 | T17: 5 | U17: =IF(COUNT(C17:T17)=18,SUM(C17:T17),"") | V17: 18 | W17: =IF(V17="","",MIN(V17,26)) | X17: =IF(OR(U17="",W17=""),"",U17-W17)
A18: Vogelius, Nico | B18: ROJO | C18: 5 | D18: 5 | E18: 5 | F18: 4 | G18: 5 | H18: 6 | I18: 5 | J18: 6 | K18: 4 | L18: 5 | M18: 5 | N18: 5 | O18: 5 | P18: 5 | Q18: 4 | R18: 5 | S18: 5 | T18: 6 | U18: =IF(COUNT(C18:T18)=18,SUM(C18:T18),"") | V18: 14 | W18: =IF(V18="","",MIN(V18,26)) | X18: =IF(OR(U18="",W18=""),"",U18-W18)
A19: Mendez, Pato | B19: ROJO | U19: =IF(COUNT(C19:T19)=18,SUM(C19:T19),"") | W19: =IF(V19="","",MIN(V19,26)) | X19: =IF(OR(U19="",W19=""),"",U19-W19)
A20: Fernandez, Lucas | B20: ROJO | U20: =IF(COUNT(C20:T20)=18,SUM(C20:T20),"") | W20: =IF(V20="","",MIN(V20,26)) | X20: =IF(OR(U20="",W20=""),"",U20-W20)
A21: Diaz Delfino, Pablo | B21: GRIS | C21: 5 | D21: 6 | E21: 7 | F21: 5 | G21: 7 | H21: 6 | I21: 6 | J21: 6 | K21: 6 | L21: 6 | M21: 4 | N21: 5 | O21: 3 | P21: 4 | Q21: 4 | R21: 4 | S21: 3 | T21: 4 | U21: =IF(COUNT(C21:T21)=18,SUM(C21:T21),"") | V21: 10 | W21: =IF(V21="","",MIN(V21,26)) | X21: =IF(OR(U21="",W21=""),"",U21-W21)
A22: Alfonso, Juan Ignacio | B22: ROJO | C22: 7 | D22: 6 | E22: 8 | F22: 3 | G22: 7 | H22: 6 | I22: 6 | J22: 5 | K22: 5 | L22: 9 | M22: 5 | N22: 5 | O22: 4 | P22: 8 | Q22: 7 | R22: 5 | S22: 3 | T22: 6 | U22: =IF(COUNT(C22:T22)=18,SUM(C22:T22),"") | V22: 23 | W22: =IF(V22="","",MIN(V22,26)) | X22: =IF(OR(U22="",W22=""),"",U22-W22)
A23: Gascon, Alejo | B23: ROJO | U23: =IF(COUNT(C23:T23)=18,SUM(C23:T23),"") | W23: =IF(V23="","",MIN(V23,26)) | X23: =IF(OR(U23="",W23=""),"",U23-W23)

Sheet F6
A1: FECHA 6 — 08 Ago 2026 — CUBA Fátima
A2: Par 72 | Individual 1v1 | Organizadores: Guevara + Vogelius
A5: HCP | B5: cancha | C5: 5 | D5: 15 | E5: 1 | F5: 7 | G5: 11 | H5: 3 | I5: 17 | J5: 13 | K5: 9 | L5: 14 | M5: 10 | N5: 2 | O5: 6 | P5: 16 | Q5: 4 | R5: 12 | S5: 18 | T5: 8
A6: PAR | C6: 5 | D6: 3 | E6: 4 | F6: 5 | G6: 4 | H6: 4 | I6: 3 | J6: 4 | K6: 4 | L6: 4 | M6: 5 | N6: 4 | O6: 4 | P6: 3 | Q6: 4 | R6: 4 | S6: 3 | T6: 5
A7: Jugador | B7: Equipo | C7: H1 | D7: H2 | E7: H3 | F7: H4 | G7: H5 | H7: H6 | I7: H7 | J7: H8 | K7: H9 | L7: H10 | M7: H11 | N7: H12 | O7: H13 | P7: H14 | Q7: H15 | R7: H16 | S7: H17 | T7: H18 | U7: Gross | V7: Hdcp día | W7: Hdcp aplic | X7: Neto
A8: Gonzalez, Agus | B8: GRIS | C8: 5 | D8: 3 | E8: 5 | F8: 5 | G8: 5 | H8: 5 | I8: 4 | J8: 4 | K8: 5 | L8: 5 | M8: 6 | N8: 5 | O8: 4 | P8: 3 | Q8: 4 | R8: 6 | S8: 4 | T8: 5 | U8: =IF(COUNT(C8:T8)=18,SUM(C8:T8),"") | V8: 7 | W8: =IF(V8="","",MIN(V8,26)) | X8: =IF(OR(U8="",W8=""),"",U8-W8)
A9: Tarasido, Gonzalo | B9: GRIS | C9: 6 | D9: 3 | E9: 6 | F9: 6 | G9: 5 | H9: 3 | I9: 4 | J9: 5 | K9: 5 | L9: 4 | M9: 7 | N9: 7 | O9: 5 | P9: 4 | Q9: 5 | R9: 4 | S9: 4 | T9: 6 | U9: =IF(COUNT(C9:T9)=18,SUM(C9:T9),"") | V9: 12 | W9: =IF(V9="","",MIN(V9,26)) | X9: =IF(OR(U9="",W9=""),"",U9-W9)
A10: Zunino, Javi | B10: GRIS | U10: =IF(COUNT(C10:T10)=18,SUM(C10:T10),"") | W10: =IF(V10="","",MIN(V10,26)) | X10: =IF(OR(U10="",W10=""),"",U10-W10)
A11: Basaldua, Ignacio | B11: GRIS | C11: 8 | D11: 3 | E11: 9 | F11: 5 | G11: 7 | H11: 5 | I11: 4 | J11: 6 | K11: 4 | L11: 6 | M11: 5 | N11: 5 | O11: 4 | P11: 4 | Q11: 7 | R11: 6 | S11: 5 | T11: 6 | U11: =IF(COUNT(C11:T11)=18,SUM(C11:T11),"") | V11: 17 | W11: =IF(V11="","",MIN(V11,26)) | X11: =IF(OR(U11="",W11=""),"",U11-W11)
A12: Pannullo, Tincho | B12: GRIS | C12: 6 | D12: 3 | E12: 5 | F12: 7 | G12: 4 | H12: 4 | I12: 4 | J12: 5 | K12: 5 | L12: 6 | M12: 11 | N12: 5 | O12: 5 | P12: 3 | Q12: 5 | R12: 7 | S12: 4 | T12: 7 | U12: =IF(COUNT(C12:T12)=18,SUM(C12:T12),"") | V12: 17 | W12: =IF(V12="","",MIN(V12,26)) | X12: =IF(OR(U12="",W12=""),"",U12-W12)
A13: Benegas, Pancho | B13: GRIS | C13: 7 | D13: 3 | E13: 8 | F13: 7 | G13: 4 | H13: 4 | I13: 2 | J13: 4 | K13: 5 | L13: 4 | M13: 7 | N13: 5 | O13: 7 | P13: 6 | Q13: 4 | R13: 5 | S13: 4 | T13: 6 | U13: =IF(COUNT(C13:T13)=18,SUM(C13:T13),"") | V13: 23 | W13: =IF(V13="","",MIN(V13,26)) | X13: =IF(OR(U13="",W13=""),"",U13-W13)
A14: Guevara, Franki | B14: GRIS | C14: 8 | D14: 3 | E14: 6 | F14: 7 | G14: 6 | H14: 5 | I14: 3 | J14: 6 | K14: 6 | L14: 6 | M14: 5 | N14: 5 | O14: 4 | P14: 4 | Q14: 6 | R14: 5 | S14: 4 | T14: 7 | U14: =IF(COUNT(C14:T14)=18,SUM(C14:T14),"") | V14: 20 | W14: =IF(V14="","",MIN(V14,26)) | X14: =IF(OR(U14="",W14=""),"",U14-W14)
A15: Dipaola, Martin | B15: GRIS | C15: 8 | D15: 3 | E15: 10 | F15: 6 | G15: 5 | H15: 8 | I15: 5 | J15: 6 | K15: 6 | L15: 4 | M15: 10 | N15: 5 | O15: 9 | P15: 5 | Q15: 6 | R15: 4 | S15: 3 | T15: 6 | U15: =IF(COUNT(C15:T15)=18,SUM(C15:T15),"") | V15: 26 | W15: =IF(V15="","",MIN(V15,26)) | X15: =IF(OR(U15="",W15=""),"",U15-W15)
A16: Gatto, Mariano | B16: ROJO | U16: =IF(COUNT(C16:T16)=18,SUM(C16:T16),"") | W16: =IF(V16="","",MIN(V16,26)) | X16: =IF(OR(U16="",W16=""),"",U16-W16)
A17: Elizalde, Juancho | B17: ROJO | C17: 7 | D17: 3 | E17: 4 | F17: 6 | G17: 5 | H17: 4 | I17: 5 | J17: 4 | K17: 5 | L17: 5 | M17: 6 | N17: 5 | O17: 5 | P17: 4 | Q17: 6 | R17: 6 | S17: 4 | T17: 5 | U17: =IF(COUNT(C17:T17)=18,SUM(C17:T17),"") | V17: 14 | W17: =IF(V17="","",MIN(V17,26)) | X17: =IF(OR(U17="",W17=""),"",U17-W17)
A18: Canónico, Agus | B18: ROJO | C18: 6 | D18: 3 | E18: 6 | F18: 7 | G18: 5 | H18: 5 | I18: 4 | J18: 5 | K18: 5 | L18: 6 | M18: 6 | N18: 6 | O18: 5 | P18: 4 | Q18: 5 | R18: 7 | S18: 5 | T18: 5 | U18: =IF(COUNT(C18:T18)=18,SUM(C18:T18),"") | V18: 16 | W18: =IF(V18="","",MIN(V18,26)) | X18: =IF(OR(U18="",W18=""),"",U18-W18)
A19: Vogelius, Nico | B19: ROJO | C19: 7 | D19: 4 | E19: 7 | F19: 6 | G19: 5 | H19: 7 | I19: 5 | J19: 5 | K19: 5 | L19: 5 | M19: 6 | N19: 5 | O19: 3 | P19: 3 | Q19: 5 | R19: 5 | S19: 4 | T19: 6 | U19: =IF(COUNT(C19:T19)=18,SUM(C19:T19),"") | V19: 15 | W19: =IF(V19="","",MIN(V19,26)) | X19: =IF(OR(U19="",W19=""),"",U19-W19)
A20: Mendez, Pato | B20: ROJO | C20: 8 | D20: 4 | E20: 6 | F20: 5 | G20: 4 | H20: 5 | I20: 3 | J20: 6 | K20: 5 | L20: 5 | M20: 6 | N20: 5 | O20: 6 | P20: 4 | Q20: 6 | R20: 5 | S20: 4 | T20: 5 | U20: =IF(COUNT(C20:T20)=18,SUM(C20:T20),"") | V20: 16 | W20: =IF(V20="","",MIN(V20,26)) | X20: =IF(OR(U20="",W20=""),"",U20-W20)
A21: Molinario, Andy | B21: ROJO | C21: 5 | D21: 3 | E21: 6 | F21: 9 | G21: 5 | H21: 5 | I21: 3 | J21: 4 | K21: 4 | L21: 4 | M21: 5 | N21: 7 | O21: 10 | P21: 8 | Q21: 6 | R21: 5 | S21: 3 | T21: 5 | U21: =IF(COUNT(C21:T21)=18,SUM(C21:T21),"") | V21: 17 | W21: =IF(V21="","",MIN(V21,26)) | X21: =IF(OR(U21="",W21=""),"",U21-W21)
A22: Scapparone, Nico | B22: ROJO | U22: =IF(COUNT(C22:T22)=18,SUM(C22:T22),"") | W22: =IF(V22="","",MIN(V22,26)) | X22: =IF(OR(U22="",W22=""),"",U22-W22)
A23: Fernandez, Lucas | B23: ROJO | C23: 6 | D23: 4 | E23: 6 | F23: 6 | G23: 6 | H23: 7 | I23: 5 | J23: 5 | K23: 6 | L23: 4 | M23: 6 | N23: 5 | O23: 6 | P23: 4 | Q23: 6 | R23: 5 | S23: 3 | T23: 9 | U23: =IF(COUNT(C23:T23)=18,SUM(C23:T23),"") | V23: 19 | W23: =IF(V23="","",MIN(V23,26)) | X23: =IF(OR(U23="",W23=""),"",U23-W23)

Sheet Match
A1: RESUMEN MATCH POR JUGADOR
A2: Jugador | B2: Equipo | C2: F1 Pts | D2: F1 Dif | E2: F2 Pts | F2: F2 Dif | G2: F3 Pts | H2: F3 Dif | I2: F4 Pts | J2: F4 Dif | K2: F5 Pts | L2: F5 Dif | M2: F6 Pts | N2: F6 Dif | O2: TOT Pts | P2: TOT Dif
A3: Gonzalez, Agus | B3: GRIS | C3: 0 | D3: -2 | G3: 0 | H3: -2 | K3: 0.5 | L3: 3 | M3: 1 | N3: 5 | O3: =SUM(C3,E3,G3,I3,K3,M3) | P3: =SUM(D3,F3,H3,J3,L3,N3)
A4: Tarasido, Gonzalo | B4: GRIS | C4: 0 | D4: -2 | E4: 0 | F4: -2 | G4: 1 | H4: 2 | I4: 0.5 | J4: 4 | K4: 0 | L4: -4 | M4: 0 | N4: -3 | O4: =SUM(C4,E4,G4,I4,K4,M4) | P4: =SUM(D4,F4,H4,J4,L4,N4)
A5: Zunino, Javi | B5: GRIS | C5: 0 | D5: -1 | K5: 0.25 | L5: 0 | M5: 1 | N5: 2 | O5: =SUM(C5,E5,G5,I5,K5,M5) | P5: =SUM(D5,F5,H5,J5,L5,N5)
A6: Basaldua, Ignacio | B6: GRIS | C6: 0 | D6: -1 | G6: 1 | H6: 1 | K6: 0.25 | L6: 0 | M6: 0 | N6: -3 | O6: =SUM(C6,E6,G6,I6,K6,M6) | P6: =SUM(D6,F6,H6,J6,L6,N6)
A7: Pannullo, Tincho | B7: GRIS | C7: 0 | D7: -7 | E7: 0 | F7: -5 | G7: 1 | H7: 1 | I7: 0.5 | J7: 1 | M7: 1 | N7: 4 | O7: =SUM(C7,E7,G7,I7,K7,M7) | P7: =SUM(D7,F7,H7,J7,L7,N7)
A8: Benegas, Pancho | B8: GRIS | C8: 0 | D8: -7 | E8: 0 | F8: -2 | G8: 0 | H8: -2 | I8: 0 | J8: -6 | K8: 0.5 | L8: 3 | M8: 1 | N8: 7 | O8: =SUM(C8,E8,G8,I8,K8,M8) | P8: =SUM(D8,F8,H8,J8,L8,N8)
A9: Guevara, Franki | B9: GRIS | C9: 0.5 | D9: 8 | E9: 1 | F9: 1 | G9: 1 | H9: 2 | I9: 0.5 | J9: 4 | K9: 0 | L9: -4 | M9: 1 | N9: 3 | O9: =SUM(C9,E9,G9,I9,K9,M9) | P9: =SUM(D9,F9,H9,J9,L9,N9)
A10: Dipaola, Martin | B10: GRIS | C10: 0.5 | D10: 8 | E10: 1 | F10: 4 | G10: 0 | H10: -4 | I10: 0.5 | J10: 1 | K10: 0.25 | L10: 0 | M10: 0.5 | N10: 0 | O10: =SUM(C10,E10,G10,I10,K10,M10) | P10: =SUM(D10,F10,H10,J10,L10,N10)
A11: Gatto, Mariano | B11: ROJO | C11: 0.5 | D11: 2 | E11: 0.5 | F11: 2 | G11: 1 | H11: 2 | I11: 0 | J11: -4 | K11: 0.25 | L11: 0 | M11: 0 | N11: -2 | O11: =SUM(C11,E11,G11,I11,K11,M11) | P11: =SUM(D11,F11,H11,J11,L11,N11)
A12: Elizalde, Juancho | B12: ROJO | C12: 0.5 | D12: 2 | E12: 0.5 | F12: 5 | G12: 1 | H12: 2 | I12: 0 | J12: -1 | K12: 0.5 | L12: 4 | M12: 0.5 | N12: 0 | O12: =SUM(C12,E12,G12,I12,K12,M12) | P12: =SUM(D12,F12,H12,J12,L12,N12)
A13: Canónico, Agus | B13: ROJO | C13: 0.5 | D13: 1 | E13: 0.5 | F13: 5 | G13: 0 | H13: -1 | I13: 0 | J13: -1 | K13: 0.25 | L13: 0 | M13: 0 | N13: -4 | O13: =SUM(C13,E13,G13,I13,K13,M13) | P13: =SUM(D13,F13,H13,J13,L13,N13)
A14: Vogelius, Nico | B14: ROJO | C14: 0.5 | D14: 1 | E14: 0 | F14: -1 | G14: 0 | H14: -1 | K14: 0.25 | L14: 0 | M14: 0 | N14: -7 | O14: =SUM(C14,E14,G14,I14,K14,M14) | P14: =SUM(D14,F14,H14,J14,L14,N14)
A15: Mendez, Pato | B15: ROJO | C15: 0.5 | D15: 7 | E15: 0.5 | F15: 2 | G15: 0 | H15: -2 | I15: 0.5 | J15: 6 | K15: 0.25 | L15: 0 | M15: 1 | N15: 3 | O15: =SUM(C15,E15,G15,I15,K15,M15) | P15: =SUM(D15,F15,H15,J15,L15,N15)
A16: Molinario, Andy | B16: ROJO | C16: 0.5 | D16: 7 | E16: 0 | F16: -4 | G16: 1 | H16: 5 | I16: 0.5 | J16: 6 | M16: 1 | N16: 3 | O16: =SUM(C16,E16,G16,I16,K16,M16) | P16: =SUM(D16,F16,H16,J16,L16,N16)
A17: Scapparone, Nico | B17: ROJO | C17: 0 | D17: -8 | M17: 0 | N17: -3 | O17: =SUM(C17,E17,G17,I17,K17,M17) | P17: =SUM(D17,F17,H17,J17,L17,N17)
A18: Fernandez, Lucas | B18: ROJO | E18: 0 | F18: -1 | G18: 1 | H18: 4 | I18: 0 | J18: -4 | K18: 0 | L18: -3 | M18: 0 | N18: -5 | O18: =SUM(C18,E18,G18,I18,K18,M18) | P18: =SUM(D18,F18,H18,J18,L18,N18)
A19: Gatto, Alejandro (Rojo) | B19: ROJO | C19: 0 | D19: -8 | E19: 0 | F19: -4 | O19: =SUM(C19,E19,G19,I19,K19,M19) | P19: =SUM(D19,F19,H19,J19,L19,N19)
A20: Alfonso, Juan Ignacio | B20: ROJO | G20: 0 | H20: -2 | K20: 0.5 | L20: 4 | O20: =SUM(C20,E20,G20,I20,K20,M20) | P20: =SUM(D20,F20,H20,J20,L20,N20)
A21: Gatto, Alejandro (Gris) | B21: GRIS | G21: 0 | H21: -5 | I21: 0.5 | J21: 1 | O21: =SUM(C21,E21,G21,I21,K21,M21) | P21: =SUM(D21,F21,H21,J21,L21,N21)
A22: Gatto, Hector | B22: GRIS | I22: 0.5 | J22: 1 | O22: =SUM(C22,E22,G22,I22,K22,M22) | P22: =SUM(D22,F22,H22,J22,L22,N22)
A23: Nissen, Germán | B23: ROJO | I23: 0 | J23: -1 | O23: =SUM(C23,E23,G23,I23,K23,M23) | P23: =SUM(D23,F23,H23,J23,L23,N23)
A24: Diaz Delfino, Pablo | B24: GRIS | K24: 0.25 | L24: 0 | O24: =SUM(C24,E24,G24,I24,K24,M24) | P24: =SUM(D24,F24,H24,J24,L24,N24)
A25: Gascon, Alejo | B25: ROJO | K25: 0 | L25: -3 | O25: =SUM(C25,E25,G25,I25,K25,M25) | P25: =SUM(D25,F25,H25,J25,L25,N25)
A26: Total GRIS | C26: =SUMIF($B$3:$B$25,"GRIS",C3:C25) | D26: =SUMIF($B$3:$B$25,"GRIS",D3:D25) | E26: =SUMIF($B$3:$B$25,"GRIS",E3:E25) | F26: =SUMIF($B$3:$B$25,"GRIS",F3:F25) | G26: =SUMIF($B$3:$B$25,"GRIS",G3:G25) | H26: =SUMIF($B$3:$B$25,"GRIS",H3:H25) | I26: =SUMIF($B$3:$B$25,"GRIS",I3:I25) | J26: =SUMIF($B$3:$B$25,"GRIS",J3:J25) | ... P26: =SUMIF($B$3:$B$25,"GRIS",P3:P25)
A27: Total ROJO | C27: =SUMIF($B$3:$B$25,"ROJO",C3:C25) | D27: =SUMIF($B$3:$B$25,"ROJO",D3:D25) | E27: =SUMIF($B$3:$B$25,"ROJO",E3:E25) | F27: =SUMIF($B$3:$B$25,"ROJO",F3:F25) | G27: =SUMIF($B$3:$B$25,"ROJO",G3:G25) | H27: =SUMIF($B$3:$B$25,"ROJO",H3:H25) | I27: =SUMIF($B$3:$B$25,"ROJO",I3:I25) | J27: =SUMIF($B$3:$B$25,"ROJO",J3:J25) | ... P27: =SUMIF($B$3:$B$25,"ROJO",P3:P25)
R34: FECHA 1 — 14-mar-2026
R35: Tipo | S35: Gris | T35: Rojo | U35: Ganador | V35: Dif Hoyos
R36: FB | S36: guevara, dipaola | T36: scapparone, gatto_ale | U36: GRIS | V36: 8
S37: pannullo, benegas | T37: molinario, mendez | U37: ROJO | V37: 7
R38: FB | S38: zunino, basaldua | T38: canonico, vogelius | U38: ROJO | V38: 1
R39: FB | S39: tarasido, gonzalez | T39: elizalde, gatto | U39: ROJO | V39: 2
R41: FECHA 2 — 11 Abr 2026
R42: Tipo | S42: Gris | T42: Rojo | U42: Ganador | V42: Dif Hoyos
R43: FB | S43: guevara | T43: vogelius, fernandez | U43: GRIS | V43: 1
S44: dipaola | T44: gatto_ale, molinario | U44: GRIS | V44: 4
R45: FB | S45: pannullo | T45: elizalde, canonico | U45: ROJO | V45: 5
R46: FB | S46: tarasido, benegas | T46: gatto, mendez | U46: ROJO | V46: 2
R48: FECHA 3 — 09 May 2026
...

Sheet Gross_Historial
A1: Jugador | B1: Equipo | C1: F1 Gross | D1: F2 Gross | E1: F3 Gross | F1: F5 Gross | G1: F6 Gross | H1: Avg | I1: Mejor
A2: Gonzalez, Agus | B2: GRIS | C2: =IFERROR(INDEX('F1'!U:U, MATCH(A2, 'F1'!A:A, 0)), "") | D2: =IFERROR(INDEX('F2'!U:U, MATCH(A2, 'F2'!A:A, 0)), "") | E2: =IFERROR(INDEX('F3'!U:U, MATCH(A2, 'F3'!A:A, 0)), "") | F2: =IFERROR(INDEX('F5'!U:U, MATCH(A2, 'F5'!A:A, 0)), "") | G2: =IFERROR(INDEX('F6'!U:U, MATCH(A2, 'F6'!A:A, 0)), "") | H2: =IFERROR(AVERAGE(C2:G2), "") | I2: =IFERROR(MIN(C2:G2), "")
A3: Tarasido, Gonzalo | B3: GRIS | C3: =IFERROR(INDEX('F1'!U:U, MATCH(A3, 'F1'!A:A, 0)), "") | D3: =IFERROR(INDEX('F2'!U:U, MATCH(A3, 'F2'!A:A, 0)), "") | E3: =IFERROR(INDEX('F3'!U:U, MATCH(A3, 'F3'!A:A, 0)), "") | F3: =IFERROR(INDEX('F5'!U:U, MATCH(A3, 'F5'!A:A, 0)), "") | G3: =IFERROR(INDEX('F6'!U:U, MATCH(A3, 'F6'!A:A, 0)), "") | H3: =IFERROR(AVERAGE(C3:G3), "") | I3: =IFERROR(MIN(C3:G3), "")
A4: Zunino, Javi | B4: GRIS | C4: =IFERROR(INDEX('F1'!U:U, MATCH(A4, 'F1'!A:A, 0)), "") | D4: =IFERROR(INDEX('F2'!U:U, MATCH(A4, 'F2'!A:A, 0)), "") | E4: =IFERROR(INDEX('F3'!U:U, MATCH(A4, 'F3'!A:A, 0)), "") | F4: =IFERROR(INDEX('F5'!U:U, MATCH(A4, 'F5'!A:A, 0)), "") | G4: =IFERROR(INDEX('F6'!U:U, MATCH(A4, 'F6'!A:A, 0)), "") | H4: =IFERROR(AVERAGE(C4:G4), "") | I4: =IFERROR(MIN(C4:G4), "")
A5: Basaldua, Ignacio | B5: GRIS | C5: =IFERROR(INDEX('F1'!U:U, MATCH(A5, 'F1'!A:A, 0)), "") | D5: =IFERROR(INDEX('F2'!U:U, MATCH(A5, 'F2'!A:A, 0)), "") | E5: =IFERROR(INDEX('F3'!U:U, MATCH(A5, 'F3'!A:A, 0)), "") | F5: =IFERROR(INDEX('F5'!U:U, MATCH(A5, 'F5'!A:A, 0)), "") | G5: =IFERROR(INDEX('F6'!U:U, MATCH(A5, 'F6'!A:A, 0)), "") | H5: =IFERROR(AVERAGE(C5:G5), "") | I5: =IFERROR(MIN(C5:G5), "")
A6: Pannullo, Tincho | B6: GRIS | C6: =IFERROR(INDEX('F1'!U:U, MATCH(A6, 'F1'!A:A, 0)), "") | D6: =IFERROR(INDEX('F2'!U:U, MATCH(A6, 'F2'!A:A, 0)), "") | E6: =IFERROR(INDEX('F3'!U:U, MATCH(A6, 'F3'!A:A, 0)), "") | F6: =IFERROR(INDEX('F5'!U:U, MATCH(A6, 'F5'!A:A, 0)), "") | G6: =IFERROR(INDEX('F6'!U:U, MATCH(A6, 'F6'!A:A, 0)), "") | H6: =IFERROR(AVERAGE(C6:G6), "") | I6: =IFERROR(MIN(C6:G6), "")
A7: Benegas, Pancho | B7: GRIS | C7: =IFERROR(INDEX('F1'!U:U, MATCH(A7, 'F1'!A:A, 0)), "") | D7: =IFERROR(INDEX('F2'!U:U, MATCH(A7, 'F2'!A:A, 0)), "") | E7: =IFERROR(INDEX('F3'!U:U, MATCH(A7, 'F3'!A:A, 0)), "") | F7: =IFERROR(INDEX('F5'!U:U, MATCH(A7, 'F5'!A:A, 0)), "") | G7: =IFERROR(INDEX('F6'!U:U, MATCH(A7, 'F6'!A:A, 0)), "") | H7: =IFERROR(AVERAGE(C7:G7), "") | I7: =IFERROR(MIN(C7:G7), "")
A8: Guevara, Franki | B8: GRIS | C8: =IFERROR(INDEX('F1'!U:U, MATCH(A8, 'F1'!A:A, 0)), "") | D8: =IFERROR(INDEX('F2'!U:U, MATCH(A8, 'F2'!A:A, 0)), "") | E8: =IFERROR(INDEX('F3'!U:U, MATCH(A8, 'F3'!A:A, 0)), "") | F8: =IFERROR(INDEX('F5'!U:U, MATCH(A8, 'F5'!A:A, 0)), "") | G8: =IFERROR(INDEX('F6'!U:U, MATCH(A8, 'F6'!A:A, 0)), "") | H8: =IFERROR(AVERAGE(C8:G8), "") | I8: =IFERROR(MIN(C8:G8), "")
A9: Dipaola, Martin | B9: GRIS | C9: =IFERROR(INDEX('F1'!U:U, MATCH(A9, 'F1'!A:A, 0)), "") | D9: =IFERROR(INDEX('F2'!U:U, MATCH(A9, 'F2'!A:A, 0)), "") | E9: =IFERROR(INDEX('F3'!U:U, MATCH(A9, 'F3'!A:A, 0)), "") | F9: =IFERROR(INDEX('F5'!U:U, MATCH(A9, 'F5'!A:A, 0)), "") | G9: =IFERROR(INDEX('F6'!U:U, MATCH(A9, 'F6'!A:A, 0)), "") | H9: =IFERROR(AVERAGE(C9:G9), "") | I9: =IFERROR(MIN(C9:G9), "")
A10: Gatto, Mariano | B10: ROJO | C10: =IFERROR(INDEX('F1'!U:U, MATCH(A10, 'F1'!A:A, 0)), "") | D10: =IFERROR(INDEX('F2'!U:U, MATCH(A10, 'F2'!A:A, 0)), "") | E10: =IFERROR(INDEX('F3'!U:U, MATCH(A10, 'F3'!A:A, 0)), "") | F10: =IFERROR(INDEX('F5'!U:U, MATCH(A10, 'F5'!A:A, 0)), "") | G10: =IFERROR(INDEX('F6'!U:U, MATCH(A10, 'F6'!A:A, 0)), "") | H10: =IFERROR(AVERAGE(C10:G10), "") | I10: =IFERROR(MIN(C10:G10), "")
A11: Elizalde, Juancho | B11: ROJO | C11: =IFERROR(INDEX('F1'!U:U, MATCH(A11, 'F1'!A:A, 0)), "") | D11: =IFERROR(INDEX('F2'!U:U, MATCH(A11, 'F2'!A:A, 0)), "") | E11: =IFERROR(INDEX('F3'!U:U, MATCH(A11, 'F3'!A:A, 0)), "") | F11: =IFERROR(INDEX('F5'!U:U, MATCH(A11, 'F5'!A:A, 0)), "") | G11: =IFERROR(INDEX('F6'!U:U, MATCH(A11, 'F6'!A:A, 0)), "") | H11: =IFERROR(AVERAGE(C11:G11), "") | I11: =IFERROR(MIN(C11:G11), "")
A12: Canónico, Agus | B12: ROJO | C12: =IFERROR(INDEX('F1'!U:U, MATCH(A12, 'F1'!A:A, 0)), "") | D12: =IFERROR(INDEX('F2'!U:U, MATCH(A12, 'F2'!A:A, 0)), "") | E12: =IFERROR(INDEX('F3'!U:U, MATCH(A12, 'F3'!A:A, 0)), "") | F12: =IFERROR(INDEX('F5'!U:U, MATCH(A12, 'F5'!A:A, 0)), "") | G12: =IFERROR(INDEX('F6'!U:U, MATCH(A12, 'F6'!A:A, 0)), "") | H12: =IFERROR(AVERAGE(C12:G12), "") | I12: =IFERROR(MIN(C12:G12), "")
A13: Vogelius, Nico | B13: ROJO | C13: =IFERROR(INDEX('F1'!U:U, MATCH(A13, 'F1'!A:A, 0)), "") | D13: =IFERROR(INDEX('F2'!U:U, MATCH(A13, 'F2'!A:A, 0)), "") | E13: =IFERROR(INDEX('F3'!U:U, MATCH(A13, 'F3'!A:A, 0)), "") | F13: =IFERROR(INDEX('F5'!U:U, MATCH(A13, 'F5'!A:A, 0)), "") | G13: =IFERROR(INDEX('F6'!U:U, MATCH(A13, 'F6'!A:A, 0)), "") | H13: =IFERROR(AVERAGE(C13:G13), "") | I13: =IFERROR(MIN(C13:G13), "")
... A18: Gatto, Alejandro | B18: — | C18: =IFERROR(INDEX('F1'!U:U, MATCH(A18, 'F1'!A:A, 0)), "") | D18: =IFERROR(INDEX('F2'!U:U, MATCH(A18, 'F2'!A:A, 0)), "") | E18: =IFERROR(INDEX('F3'!U:U, MATCH(A18, 'F3'!A:A, 0)), "") | F18: =IFERROR(INDEX('F5'!U:U, MATCH(A18, 'F5'!A:A, 0)), "") | G18: =IFERROR(INDEX('F6'!U:U, MATCH(A18, 'F6'!A:A, 0)), "") | H18: =IFERROR(AVERAGE(C18:G18), "") | I18: =IFERROR(MIN(C18:G18), "")

Sheet Medal_Calc
A1: Posición | B1: Pts base | C1: Mult F9 (×1.5) | D1: Mult F10 (×2)
A2: 1 | B2: 500 | C2: 750 | D2: 1000
A3: 2 | B3: 300 | C3: 450 | D3: 600
A4: 3 | B4: 200 | C4: 300 | D4: 400
A5: 4 | B5: 150 | C5: 225 | D5: 300
A6: 5 | B6: 120 | C6: 180 | D6: 240
A7: 6 | B7: 100 | C7: 150 | D7: 200
A8: 7 | B8: 90 | C8: 135 | D8: 180
A9: 8 | B9: 80 | C9: 120 | D9: 160
A10: 9 | B10: 75 | C10: 112.5 | D10: 150
A11: 10 | B11: 70 | C11: 105 | D11: 140
A12: 11 | B12: 20 | C12: 30 | D12: 40
A13: 12 | B13: 20 | C13: 30 | D13: 40
... A17: 16 | B17: 0 | C17: 0 | D17: 0
A20: Nota: F1-F8 multiplicador = 1. F9 = 1.5. F10 = 2.

Sheet Medal_Fechas
A1: Jugador | B1: Equipo | C1: F1 Neto | D1: F1 Pos | E1: F1 Pts | F1: F2 Neto | G1: F2 Pos | H1: F2 Pts | I1: F3 Neto | J1: F3 Pos | K1: F3 Pts | L1: F5 Neto | M1: F5 Pos | N1: F5 Pts | O1: F6 Neto | P1: F6 Pos | Q1: F6 Pts
A2: Gonzalez, Agus | B2: GRIS | C2: 78 | D2: 11 | E2: 20 | L2: 83 | M2: 10 | N2: 45 | O2: 76 | P2: 3 | Q2: 156.67
A3: Tarasido, Gonzalo | B3: GRIS | C3: 75 | D3: 9 | E3: 72.5 | F3: 85 | G3: 11 | H3: 20 | I3: 76 | J3: 2 | K3: 300 | L3: 81 | M3: 7 | N3: 85 | O3: 77 | P3: 6 | Q3: 100
A4: Zunino, Javi | B4: GRIS | C4: 72 | D4: 6 | E4: 95
A5: Basaldua, Ignacio | B5: GRIS | C5: 79 | D5: 13 | E5: 20 | I5: 78 | J5: 4 | K5: 123.33 | L5: 78 | M5: 3 | N5: 156.67 | O5: 82 | P5: 12 | Q5: 20
A6: Pannullo, Tincho | B6: GRIS | C6: 82 | D6: 14 | E6: 20 | F6: 77 | G6: 10 | H6: 70 | I6: 77 | J6: 3 | K6: 200 | O6: 79 | P6: 8 | Q6: 77.5
A7: Benegas, Pancho | B7: GRIS | C7: 92 | D7: 15 | E7: 0 | F7: 73 | G7: 4 | H7: 123.33 | I7: 78 | J7: 4 | K7: 123.33 | L7: 80 | M7: 6 | N7: 100 | O7: 69 | P7: 1 | Q7: 500
A8: Guevara, Franki | B8: GRIS | C8: 67 | D8: 1 | E8: 400 | F8: 75 | G8: 8 | H8: 80 | I8: 80 | J8: 8 | K8: 80 | L8: 78 | M8: 3 | N8: 156.67 | O8: 76 | P8: 3 | Q8: 156.67
A9: Dipaola, Martin | B9: GRIS | C9: 71 | D9: 5 | E9: 120 | F9: 73 | G9: 4 | H9: 123.33 | I9: 84 | J9: 10 | K9: 36.67 | L9: 88 | M9: 12 | N9: 20 | O9: 83 | P9: 13 | Q9: 20
A10: Gatto, Mariano | B10: ROJO | C10: 72 | D10: 6 | E10: 95 | F10: 66 | G10: 1 | H10: 500 | I10: 85 | J10: 13 | K10: 20 | L10: 78 | M10: 3 | N10: 156.67
A11: Elizalde, Juancho | B11: ROJO | C11: 73 | D11: 8 | E11: 80 | F11: 70 | G11: 2 | H11: 250 | I11: 79 | J11: 7 | K11: 90 | L11: 74 | M11: 1 | N11: 500 | O11: 75 | P11: 2 | Q11: 300
A12: Canónico, Agus | B12: ROJO | C12: 78 | D12: 11 | E12: 20 | F12: 73 | G12: 4 | H12: 123.33 | I12: 82 | J12: 9 | K12: 75 | L12: 83 | M12: 10 | N12: 45 | O12: 79 | P12: 8 | Q12: 77.5
A13: Vogelius, Nico | B13: ROJO | C13: 67 | D13: 1 | E13: 400 | F13: 85 | G13: 11 | H13: 20 | I13: 78 | J13: 4 | K13: 123.33 | L13: 76 | M13: 2 | N13: 300 | O13: 78 | P13: 7 | Q13: 90
A14: Mendez, Pato | B14: ROJO | C14: 69 | D14: 3 | E14: 175 | F14: 74 | G14: 7 | H14: 90 | I14: 85 | J14: 13 | K14: 20 | O14: 76 | P14: 3 | Q14: 156.67
A15: Molinario, Andy | B15: ROJO | C15: 69 | D15: 3 | E15: 175 | F15: 76 | G15: 9 | H15: 75 | I15: 84 | J15: 10 | K15: 36.67 | O15: 80 | P15: 10 | Q15: 45
A16: Scapparone, Nico | B16: ROJO | C16: 75 | D16: 9 | E16: 72.5
A17: Fernandez, Lucas | B17: ROJO | F17: 70 | G17: 2 | H17: 250 | I17: 69 | J17: 1 | K17: 500 | O17: 80 | P17: 10 | Q17: 45
A18: Gatto, Alejandro | B18: — | C18: 97 | D18: 16 | E18: 0 | F18: 89 | G18: 13 | H18: 20 | I18: 101 | J18: 15 | K18: 0
A19: Alfonso, Juan Ignacio | B19: ROJO | I19: 84 | J19: 10 | K19: 36.67 | L19: 82 | M19: 9 | N19: 75
A20: sup_shaw | B20: —
A21: Diaz Delfino, Pablo | B21: GRIS | L21: 81 | M21: 7 | N21: 85

Sheet Medal_Consolidado
A1: Jugador | B1: Equipo | C1: F1 Pts | D1: F2 Pts | E1: F3 Pts | F1: F5 Pts | G1: F6 Pts | H1: TOTAL
A2: Fernandez, Lucas | B2: ROJO | C2: =IFERROR(VLOOKUP(A2, Medal_Fechas!$A:$K, 5, FALSE()), 0) | D2: =IFERROR(VLOOKUP(A2, Medal_Fechas!$A:$K, 8, FALSE()), 0) | E2: =IFERROR(VLOOKUP(A2, Medal_Fechas!$A:$K, 11, FALSE()), 0) | F2: =IFERROR(VLOOKUP(A2, Medal_Fechas!$A:$N, 14, FALSE()), 0) | G2: =IFERROR(VLOOKUP(A2, Medal_Fechas!$A:$Q, 17, FALSE()), 0) | H2: =SUM(C2:G2)
A3: Gatto, Mariano | B3: ROJO | C3: =IFERROR(VLOOKUP(A3, Medal_Fechas!$A:$K, 5, FALSE()), 0) | D3: =IFERROR(VLOOKUP(A3, Medal_Fechas!$A:$K, 8, FALSE()), 0) | E3: =IFERROR(VLOOKUP(A3, Medal_Fechas!$A:$K, 11, FALSE()), 0) | F3: =IFERROR(VLOOKUP(A3, Medal_Fechas!$A:$N, 14, FALSE()), 0) | G3: =IFERROR(VLOOKUP(A3, Medal_Fechas!$A:$Q, 17, FALSE()), 0) | H3: =SUM(C3:G3)
A4: Guevara, Franki | B4: GRIS | C4: =IFERROR(VLOOKUP(A4, Medal_Fechas!$A:$K, 5, FALSE()), 0) | D4: =IFERROR(VLOOKUP(A4, Medal_Fechas!$A:$K, 8, FALSE()), 0) | E4: =IFERROR(VLOOKUP(A4, Medal_Fechas!$A:$K, 11, FALSE()), 0) | F4: =IFERROR(VLOOKUP(A4, Medal_Fechas!$A:$N, 14, FALSE()), 0) | G4: =IFERROR(VLOOKUP(A4, Medal_Fechas!$A:$Q, 17, FALSE()), 0) | H4: =SUM(C4:G4)
A5: Vogelius, Nico | B5: ROJO | C5: =IFERROR(VLOOKUP(A5, Medal_Fechas!$A:$K, 5, FALSE()), 0) | D5: =IFERROR(VLOOKUP(A5, Medal_Fechas!$A:$K, 8, FALSE()), 0) | E5: =IFERROR(VLOOKUP(A5, Medal_Fechas!$A:$K, 11, FALSE()), 0) | F5: =IFERROR(VLOOKUP(A5, Medal_Fechas!$A:$N, 14, FALSE()), 0) | G5: =IFERROR(VLOOKUP(A5, Medal_Fechas!$A:$Q, 17, FALSE()), 0) | H5: =SUM(C5:G5)
A6: Elizalde, Juancho | B6: ROJO | C6: =IFERROR(VLOOKUP(A6, Medal_Fechas!$A:$K, 5, FALSE()), 0) | D6: =IFERROR(VLOOKUP(A6, Medal_Fechas!$A:$K, 8, FALSE()), 0) | E6: =IFERROR(VLOOKUP(A6, Medal_Fechas!$A:$K, 11, FALSE()), 0) | F6: =IFERROR(VLOOKUP(A6, Medal_Fechas!$A:$N, 14, FALSE()), 0) | G6: =IFERROR(VLOOKUP(A6, Medal_Fechas!$A:$Q, 17, FALSE()), 0) | H6: =SUM(C6:G6)
A7: Tarasido, Gonzalo | B7: GRIS | C7: =IFERROR(VLOOKUP(A7, Medal_Fechas!$A:$K, 5, FALSE()), 0) | D7: =IFERROR(VLOOKUP(A7, Medal_Fechas!$A:$K, 8, FALSE()), 0) | E7: =IFERROR(VLOOKUP(A7, Medal_Fechas!$A:$K, 11, FALSE()), 0) | F7: =IFERROR(VLOOKUP(A7, Medal_Fechas!$A:$N, 14, FALSE()), 0) | G7: =IFERROR(VLOOKUP(A7, Medal_Fechas!$A:$Q, 17, FALSE()), 0) | H7: =SUM(C7:G7)
A8: Pannullo, Tincho | B8: GRIS | C8: =IFERROR(VLOOKUP(A8, Medal_Fechas!$A:$K, 5, FALSE()), 0) | D8: =IFERROR(VLOOKUP(A8, Medal_Fechas!$A:$K, 8, FALSE()), 0) | E8: =IFERROR(VLOOKUP(A8, Medal_Fechas!$A:$K, 11, FALSE()), 0) | F8: =IFERROR(VLOOKUP(A8, Medal_Fechas!$A:$N, 14, FALSE()), 0) | G8: =IFERROR(VLOOKUP(A8, Medal_Fechas!$A:$Q, 17, FALSE()), 0) | H8: =SUM(C8:G8)
A9: Molinario, Andy | B9: ROJO | C9: =IFERROR(VLOOKUP(A9, Medal_Fechas!$A:$K, 5, FALSE()), 0) | D9: =IFERROR(VLOOKUP(A9, Medal_Fechas!$A:$K, 8, FALSE()), 0) | E9: =IFERROR(VLOOKUP(A9, Medal_Fechas!$A:$K, 11, FALSE()), 0) | F9: =IFERROR(VLOOKUP(A9, Medal_Fechas!$A:$N, 14, FALSE()), 0) | G9: =IFERROR(VLOOKUP(A9, Medal_Fechas!$A:$Q, 17, FALSE()), 0) | H9: =SUM(C9:G9)
A10: Mendez, Pato | B10: ROJO | C10: =IFERROR(VLOOKUP(A10, Medal_Fechas!$A:$K, 5, FALSE()), 0) | D10: =IFERROR(VLOOKUP(A10, Medal_Fechas!$A:$K, 8, FALSE()), 0) | E10: =IFERROR(VLOOKUP(A10, Medal_Fechas!$A:$K, 11, FALSE()), 0) | F10: =IFERROR(VLOOKUP(A10, Medal_Fechas!$A:$N, 14, FALSE()), 0) | G10: =IFERROR(VLOOKUP(A10, Medal_Fechas!$A:$Q, 17, FALSE()), 0) | H10: =SUM(C10:G10)
A11: Dipaola, Martin | B11: GRIS | C11: =IFERROR(VLOOKUP(A11, Medal_Fechas!$A:$K, 5, FALSE()), 0) | D11: =IFERROR(VLOOKUP(A11, Medal_Fechas!$A:$K, 8, FALSE()), 0) | E11: =IFERROR(VLOOKUP(A11, Medal_Fechas!$A:$K, 11, FALSE()), 0) | F11: =IFERROR(VLOOKUP(A11, Medal_Fechas!$A:$N, 14, FALSE()), 0) | G11: =IFERROR(VLOOKUP(A11, Medal_Fechas!$A:$Q, 17, FALSE()), 0) | H11: =SUM(C11:G11)
A12: Benegas, Pancho | B12: GRIS | C12: =IFERROR(VLOOKUP(A12, Medal_Fechas!$A:$K, 5, FALSE()), 0) | D12: =IFERROR(VLOOKUP(A12, Medal_Fechas!$A:$K, 8, FALSE()), 0) | E12: =IFERROR(VLOOKUP(A12, Medal_Fechas!$A:$K, 11, FALSE()), 0) | F12: =IFERROR(VLOOKUP(A12, Medal_Fechas!$A:$N, 14, FALSE()), 0) | G12: =IFERROR(VLOOKUP(A12, Medal_Fechas!$A:$Q, 17, FALSE()), 0) | H12: =SUM(C12:G12)
A13: Canónico, Agus | B13: ROJO | C13: =IFERROR(VLOOKUP(A13, Medal_Fechas!$A:$K, 5, FALSE()), 0) | D13: =IFERROR(VLOOKUP(A13, Medal_Fechas!$A:$K, 8, FALSE()), 0) | E13: =IFERROR(VLOOKUP(A13, Medal_Fechas!$A:$K, 11, FALSE()), 0) | F13: =IFERROR(VLOOKUP(A13, Medal_Fechas!$A:$N, 14, FALSE()), 0) | G13: =IFERROR(VLOOKUP(A13, Medal_Fechas!$A:$Q, 17, FALSE()), 0) | H13: =SUM(C13:G13)
... A18: Gatto, Alejandro | B18: — | C18: =IFERROR(VLOOKUP(A18, Medal_Fechas!$A:$K, 5, FALSE()), 0) | D18: =IFERROR(VLOOKUP(A18, Medal_Fechas!$A:$K, 8, FALSE()), 0) | E18: =IFERROR(VLOOKUP(A18, Medal_Fechas!$A:$K, 11, FALSE()), 0) | F18: =IFERROR(VLOOKUP(A18, Medal_Fechas!$A:$N, 14, FALSE()), 0) | G18: =IFERROR(VLOOKUP(A18, Medal_Fechas!$A:$Q, 17, FALSE()), 0) | H18: =SUM(C18:G18)

Sheet Fixture
A1: F# | B1: Fecha | C1: Cancha | D1: Modalidad | E1: Criterio | F1: Organizadores | G1: Estado
A2: 1 | B2: 14-Mar-2026 | C2: CUBA Fátima | D2: Fourball 2v2 | E2: Neto | F2: Gatto + Zunino | G2: Jugada
A3: 2 | B3: 11-Abr-2026 | C3: CUBA Fátima | D3: Fourball 2v2 | E3: Neto | F3: — | G3: Jugada
A4: 3 | B4: 09-May-2026 | C4: SHA Hebraica | D4: Individual | E4: Neto | F4: Gonzalez + Tarasido | G4: Jugada
A5: 4 | B5: 06-Jun-2026 | C5: CUBA Fátima | D5: Fourball 2v2 | E5: Neto | F5: Pannullo + Basaldua | G5: Jugada (solo match — niebla)
A6: 5 | B6: 04-Jul-2026 | C6: La Orquídea | D6: Fourball 2v2 | E6: Neto | F6: Basaldua + Canónico | G6: Jugada
A7: 6 | B7: 08-Ago-2026 | C7: CUBA Fátima | D7: Individual 1v1 | E7: Neto | F7: Guevara + Vogelius | G7: Jugada
A8: 7 | B8: 12-Sep-2026 | C8: CUBA Fátima | D8: Fourball 2v2 | E8: Neto | F8: Scapparone + Benegas | G8: Pendiente
A9: 8 | B9: 03-Oct-2026 | C9: CUBA Fátima | D9: Individual 1v1 | E9: Neto | F9: Elizalde + Mendez | G9: Pendiente
A10: 9 | B10: 04-Nov-2026 | C10: GIRA | D10: Fourball inverso | E10: Neto ×1.5 | F10: GIRA | G10: Pendiente
A11: 10 | B11: 09-Nov-2026 | C11: GIRA FINAL | D11: Individual 1v1 | E11: Neto ×2 | F11: GIRA | G11: Pendiente

Sheet Historico
A1: Jugador | B1: 2016 | F1: 2017 | J1: 2018 | N1: 2019 | R1: 2020 | V1: 2021 | Z1: 2022 | AD1: 2023 | AH1: 2024 | AL1: 2025
B2: FJ | C2: FG | D2: AG | E2: AN | F2: FJ | G2: FG | H2: AG | I2: AN | J2: FJ | K2: FG | L2: AG | M2: AN | N2: FJ | O2: FG | P2: AG | Q2: AN | R2: FJ | S2: FG | T2: AG | U2: AN | V2: FJ | W2: FG | X2: AG | Y2: AN | Z2: FJ | AA2: FG | AB2: AG | AC2: AN | AD2: FJ | AE2: FG | AF2: AG | AG2: AN | AH2: FJ | AI2: FG | AJ2: AG | AK2: AN | AL2: FJ | AM2: FG | AN2: AG | AO2: AN
A3: Gonzalez, Agustín | Z3: 7 | AA3: 0 | AB3: 83.3 | AC3: 74.9 | AD3: 8 | AE3: 0 | AF3: 84.6 | AG3: 77.9 | AH3: 7 | AI3: 0 | AJ3: 81.4 | AK3: 75.9 | AL3: 7 | AM3: 0 | AN3: 86.9 | AO3: 78.3
A4: Tarasido, Gonzalo | F4: 1 | G4: 0 | H4: 88 | I4: 77 | J4: 7 | K4: 2 | L4: 88 | M4: 75.1 | N4: 7 | O4: 0 | P4: 90.3 | Q4: 78.3 | V4: 5 | W4: 0 | X4: 91.8 | Y4: 80 | Z4: 8 | AA4: 0 | AB4: 93 | AC4: 78.8 | AD4: 7 | AE4: 1 | AF4: 94 | AG4: 78.3 | AH4: 9 | AI4: 2 | AJ4: 89.1 | AK4: 75.1 | AL4: 9 | AM4: 1 | AN4: 87.9 | AO4: 76.3
A5: Zunino, Javier | B5: 4 | C5: 0 | F5: 6 | G5: 1 | H5: 93.3 | I5: 81.8 | J5: 7 | K5: 0 | L5: 95.9 | M5: 81.6 | V5: 3 | W5: 1 | X5: 90.7 | Y5: 72.7 | Z5: 9 | AA5: 1 | AB5: 86.9 | AC5: 74.3 | AD5: 8 | AE5: 0 | AF5: 90.6 | AG5: 80.5 | AH5: 9 | AI5: 0 | AJ5: 90.4 | AK5: 80.6 | AL5: 10 | AM5: 1 | AN5: 88.4 | AO5: 75.5
A6: Basaldua, Ignacio | V6: 8 | W6: 1 | X6: 95.8 | Y6: 77.4 | Z6: 5 | AA6: 0 | AB6: 101.4 | AC6: 83.2 | AD6: 7 | AE6: 0 | AF6: 97.7 | AG6: 80 | AH6: 9 | AI6: 1 | AJ6: 90.9 | AK6: 75 | AL6: 10 | AM6: 2 | AN6: 91.3 | AO6: 75.5
A7: Pannullo, Martín | B7: 4 | C7: 0 | D7: 124 | F7: 6 | G7: 0 | H7: 105.3 | I7: 78.3 | J7: 8 | K7: 2 | L7: 107 | M7: 80 | N7: 7 | O7: 2 | P7: 101.3 | Q7: 75.3 | V7: 6 | W7: 0 | X7: 102.2 | Y7: 78.3 | Z7: 7 | AA7: 0 | AB7: 101.7 | AC7: 79.1 | AD7: 9 | AE7: 3 | AF7: 95.9 | AG7: 73.4 | AH7: 10 | AI7: 1 | AJ7: 94.9 | AK7: 77.3 | AL7: 9 | AM7: 1 | AN7: 95.9 | AO7: 80.7
A8: Benegas, Francisco | B8: 4 | C8: 0 | D8: 105 | F8: 5 | G8: 0 | H8: 104.6 | I8: 81.6 | J8: 8 | K8: 1 | L8: 103.9 | M8: 79.1 | N8: 6 | O8: 0 | P8: 107.3 | Q8: 83.2 | V8: 9 | W8: 1 | X8: 101 | Y8: 76.1 | Z8: 7 | AA8: 0 | AB8: 100.9 | AC8: 75.1 | AD8: 8 | AE8: 1 | AF8: 100 | AG8: 75.2 | AH8: 10 | AI8: 1 | AJ8: 99 | AK8: 77 | AL8: 8 | AM8: 0 | AN8: 98.1 | AO8: 78.6
A9: Guevara, Francisco | B9: 4 | C9: 0 | D9: 112.3 | F9: 7 | G9: 0 | H9: 100.9 | I9: 76.7 | J9: 8 | K9: 0 | L9: 101.2 | M9: 78.2 | N9: 6 | O9: 0 | P9: 105 | Q9: 82.7 | V9: 5 | W9: 0 | X9: 103.6 | Y9: 78.8 | Z9: 6 | AA9: 0 | AB9: 102.5 | AC9: 77.5 | AD9: 9 | AE9: 0 | AF9: 98.6 | AG9: 77.4 | AH9: 8 | AI9: 1 | AJ9: 97 | AK9: 76.6 | AL9: 10 | AM9: 0 | AN9: 98.9 | AO9: 78.7
A10: Dipaola, Martín | F10: 2 | G10: 0 | H10: 118.5 | I10: 93.5 | Z10: 7 | AA10: 0 | AB10: 108.4 | AC10: 82.9 | AD10: 7 | AE10: 0 | AF10: 103.1 | AG10: 77.1 | AH10: 6 | AI10: 0 | AJ10: 102.2 | AK10: 77 | AL10: 6 | AM10: 0 | AN10: 100 | AO10: 78
A11: Gatto, Mariano | B11: 4 | C11: 1 | D11: 97.5 | F11: 7 | G11: 2 | H11: 94.4 | I11: 75.9 | J11: 8 | K11: 1 | L11: 95.1 | M11: 81.1 | N11: 8 | O11: 0 | P11: 90 | Q11: 77.4 | V11: 8 | W11: 2 | X11: 84.8 | Y11: 74.4 | Z11: 7 | AA11: 0 | AB11: 87.7 | AC11: 76.4 | AD11: 9 | AE11: 0 | AF11: 84.8 | AG11: 75.7 | AH11: 9 | AI11: 0 | AJ11: 87.2 | AK11: 78 | AL11: 9 | AM11: 1 | AN11: 85.9 | AO11: 76
A12: Elizalde, Juan Pedro | B12: 4 | C12: 0 | D12: 98.7 | F12: 7 | G12: 0 | H12: 94.9 | I12: 79.3 | J12: 8 | K12: 1 | L12: 93.4 | M12: 77.1 | N12: 8 | O12: 2 | P12: 92.4 | Q12: 76.6 | V12: 9 | W12: 1 | X12: 88.4 | Y12: 76 | Z12: 9 | AA12: 2 | AB12: 88.3 | AC12: 76.9 | AD12: 9 | AE12: 2 | AF12: 82.6 | AG12: 74.9 | AH12: 7 | AI12: 0 | AJ12: 87.4 | AK12: 80.3 | AL12: 10 | AM12: 0 | AN12: 91 | AO12: 80.9
A13: Canónico, Agustín | B13: 4 | C13: 0 | D13: 95.3 | F13: 8 | G13: 0 | H13: 97.6 | I13: 80.2 | J13: 7 | K13: 0 | L13: 96.6 | M13: 77.1 | N13: 8 | O13: 2 | P13: 92.4 | Q13: 73.2 | V13: 5 | W13: 1 | X13: 93 | Y13: 76.2 | Z13: 7 | AA13: 1 | AB13: 93.9 | AC13: 76.1 | AD13: 7 | AE13: 1 | AF13: 92 | AG13: 77.3 | AH13: 8 | AI13: 0 | AJ13: 94.9 | AK13: 80.5 | AL13: 8 | AM13: 0 | AN13: 95.5 | AO13: 81.2
A14: Vogelius, Nicolás | B14: 4 | C14: 0 | D14: 106.7 | F14: 7 | G14: 1 | H14: 96.9 | I14: 80.9 | J14: 5 | K14: 0 | L14: 99 | M14: 82.2 | N14: 7 | O14: 0 | P14: 96.3 | Q14: 78.4 | V14: 8 | W14: 0 | X14: 94.8 | Y14: 76.2 | Z14: 9 | AA14: 4 | AB14: 91.4 | AC14: 73.2 | AD14: 8 | AE14: 1 | AF14: 95.2 | AG14: 80.8 | AH14: 8 | AI14: 1 | AJ14: 93.2 | AK14: 78.2 | AL14: 10 | AM14: 2 | AN14: 92.1 | AO14: 75.6
A15: Méndez, Gastón | B15: 4 | C15: 1 | D15: 103.3 | F15: 6 | G15: 0 | H15: 105.2 | I15: 85.2 | J15: 7 | K15: 1 | L15: 99.4 | M15: 78.3 | N15: 7 | O15: 0 | P15: 101.7 | Q15: 79.7 | V15: 9 | W15: 1 | X15: 97.6 | Y15: 76.1 | Z15: 7 | AA15: 0 | AB15: 94.6 | AC15: 73.1 | AD15: 9 | AE15: 1 | AF15: 99.1 | AG15: 79.8 | AH15: 10 | AI15: 0 | AJ15: 95 | AK15: 76.5 | AL15: 10 | AM15: 2 | AN15: 95.8 | AO15: 77.9
A16: Molinario, Andrés | B16: 4 | C16: 0 | D16: 117 | F16: 7 | G16: 2 | H16: 100.4 | I16: 75.6 | J16: 6 | K16: 0 | L16: 105.7 | M16: 82.5 | N16: 3 | O16: 0 | P16: 106 | Q16: 82.7 | V16: 8 | W16: 1 | X16: 100.9 | Y16: 79 | Z16: 7 | AA16: 1 | AB16: 97.6 | AC16: 75.1 | AD16: 7 | AE16: 1 | AF16: 94.7 | AG16: 74.4 | AH16: 9 | AI16: 1 | AJ16: 99.4 | AK16: 81.1 | AL16: 8 | AM16: 1 | AN16: 95.5 | AO16: 77.5
A17: Scapparone, Nicolás | AD17: 1 | AE17: 0 | AF17: 105 | AG17: 83 | AH17: 5 | AI17: 0 | AJ17: 99.8 | AK17: 77.8 | AL17: 5 | AM17: 0 | AN17: 99 | AO17: 81
A18: Fernandez, Lucas | V18: 8 | W18: 0 | X18: 103.5 | Y18: 77.5 | Z18: 6 | AA18: 0 | AB18: 104.5 | AC18: 83.5 | AD18: 6 | AE18: 0 | AF18: 100.5 | AG18: 79.5 | AH18: 7 | AI18: 1 | AJ18: 101.1 | AK18: 79 | AL18: 10 | AM18: 1 | AN18: 98.4 | AO18: 78.6
A19: Gatto, Alejandro
A20: Canónico, Nacho | B20: 4 | C20: 1 | D20: 100.7 | F20: 5 | G20: 0 | H20: 102.8 | I20: 80.2
A21: Nielsen, Juanchi | B21: 4 | C21: 0 | D21: 108.3 | F21: 5 | G21: 0 | H21: 103.4 | I21: 83.2
A22: Copello, Santi | F22: 8 | G22: 0 | H22: 97.5 | I22: 73.1
A23: Delger, Martin | F23: 5 | G23: 0 | H23: 105.4 | I23: 80.4
A24: Señorans, Julio | F24: 6 | G24: 0 | H24: 98.3 | I24: 84.3
A25: Sánchez Ricoy, Jorge | N25: 2 | O25: 1 | P25: 93 | Q25: 70
A26: Hack, Federico | N26: 1 | O26: 0 | P26: 103 | Q26: 82
A27: Abreu, Santiago
A28: Miceli, Julian (INV) | V28: 3 | W28: 1 | X28: 94.7 | Y28: 74.3 | Z28: 1 | AA28: 0 | AB28: 99 | AC28: 80
A29: Miranda, Francisco | V29: 1 | W29: 0 | X29: 92 | Y29: 77
A30: Diaz Andrade, Juampi | Z30: 4 | AA30: 0 | AB30: 112 | AC30: 87
A31: Perez A., Nacho | Z31: 2 | AA31: 0 | AB31: 90 | AC31: 70.5 | AD31: 6 | AE31: 1 | AF31: 93.5 | AG31: 76.3
A32: Lavalle, Joaquin | Z32: 1 | AA32: 0 | AB32: 85 | AC32: 79
A33: Uribelarrea, Rafael (INV) | AH33: 2 | AI33: 0 | AJ33: 102.5 | AK33: 83.5
A34: Robles, Juancho | AH34: 4 | AI34: 2 | AJ34: 87.8 | AK34: 72.5 | AL34: 3 | AM34: 0 | AN34: 89 | AO34: 77.3
A35: Alfonso, Juani | AH35: 4 | AI35: 0 | AJ35: 110.8 | AK35: 84.8 | AL35: 2 | AM35: 0 | AN35: 98 | AO35: 75.5
A36: Troncoso, Tati | AH36: 1 | AI36: 0 | AJ36: 92 | AK36: 82
A37: Hector, Gatto | J37: 3 | K37: 1 | L37: 90 | M37: 77 | N37: 2 | O37: 0 | P37: 96.5 | Q37: 84.5 | Z37: 1 | AA37: 1 | AB37: 83 | AC37: 67 | AH37: 2 | AI37: 0 | AJ37: 89 | AK37: 74.5 | AL37: 2 | AM37: 0 | AN37: 89.5 | AO37: 77.5
A38: Basaldua, Javier | AH38: 1 | AI38: 0 | AJ38: 82 | AK38: 71
A39: Vigil, Tomas | AL39: 1 | AM39: 0 | AN39: 95 | AO39: 77

Sheet Jugadores
A1: ID | B1: Nombre completo | C1: Sobrenombre | D1: Equipo | E1: Hdcp default
A2: gonzalez | B2: Gonzalez, Agus | C2: Agus | D2: GRIS | E2: 8
A3: tarasido | B3: Tarasido, Gonzalo | C3: Gonzalo | D3: GRIS | E3: 11
A4: zunino | B4: Zunino, Javi | C4: Javi | D4: GRIS | E4: 14
A5: basaldua | B5: Basaldua, Ignacio | C5: Nacho | D5: GRIS | E5: 16
A6: pannullo | B6: Pannullo, Tincho | C6: Tincho | D6: GRIS | E6: 15
A7: benegas | B7: Benegas, Pancho | C7: Pancho | D7: GRIS | E7: 21
A8: guevara | B8: Guevara, Franki | C8: Franki | D8: GRIS | E8: 18
A9: dipaola | B9: Dipaola, Martin | C9: Martin | D9: GRIS | E9: 22
A10: gatto | B10: Gatto, Mariano | C10: Mariano | D10: ROJO | E10: 9
A11: elizalde | B11: Elizalde, Juancho | C11: Juancho | D11: ROJO | E11: 12
A12: canonico | B12: Canónico, Agus | C12: Cano | D12: ROJO | E12: 17
A13: vogelius | B13: Vogelius, Nico | C13: Nico | D13: ROJO | E13: 14
... A18: gatto_ale | B18: Gatto, Alejandro | C18: Ale | D18: SUPLENTE | E18: 14
